Traceback (most recent call last):
  File "/Library/Frameworks/Python.framework/Versions/3.10/lib/python3.10/site-packages/jupyter_cache/executors/utils.py", line 51, in single_nb_execution
    executenb(
  File "/Library/Frameworks/Python.framework/Versions/3.10/lib/python3.10/site-packages/nbclient/client.py", line 1093, in execute
    return NotebookClient(nb=nb, resources=resources, km=km, **kwargs).execute()
  File "/Library/Frameworks/Python.framework/Versions/3.10/lib/python3.10/site-packages/nbclient/util.py", line 84, in wrapped
    return just_run(coro(*args, **kwargs))
  File "/Library/Frameworks/Python.framework/Versions/3.10/lib/python3.10/site-packages/nbclient/util.py", line 62, in just_run
    return loop.run_until_complete(coro)
  File "/Library/Frameworks/Python.framework/Versions/3.10/lib/python3.10/asyncio/base_events.py", line 641, in run_until_complete
    return future.result()
  File "/Library/Frameworks/Python.framework/Versions/3.10/lib/python3.10/site-packages/nbclient/client.py", line 559, in async_execute
    await self.async_execute_cell(
  File "/Library/Frameworks/Python.framework/Versions/3.10/lib/python3.10/site-packages/nbclient/client.py", line 854, in async_execute_cell
    self._check_raise_for_error(cell, exec_reply)
  File "/Library/Frameworks/Python.framework/Versions/3.10/lib/python3.10/site-packages/nbclient/client.py", line 756, in _check_raise_for_error
    raise CellExecutionError.from_cell_and_msg(cell, exec_reply_content)
nbclient.exceptions.CellExecutionError: An error occurred while executing the following cell:
------------------
tuned = pd.read_csv("../../results/tables/tuned_para.csv", index_col=0, sep=",")
glue("tuned_para", tuned)
glue("para1", tuned.iloc[0]["kneighborsclassifier__n_neighbors"])
glue("para2", tuned.iloc[0]["kneighborsclassifier__weights"])
glue("recall", np.around(tuned.iloc[0]["knn_best_score"], 3))
------------------

[0;31m---------------------------------------------------------------------------[0m
[0;31mKeyError[0m                                  Traceback (most recent call last)
[0;32m/Library/Frameworks/Python.framework/Versions/3.10/lib/python3.10/site-packages/pandas/core/indexes/base.py[0m in [0;36mget_loc[0;34m(self, key, method, tolerance)[0m
[1;32m   3620[0m             [0;32mtry[0m[0;34m:[0m[0;34m[0m[0;34m[0m[0m
[0;32m-> 3621[0;31m                 [0;32mreturn[0m [0mself[0m[0;34m.[0m[0m_engine[0m[0;34m.[0m[0mget_loc[0m[0;34m([0m[0mcasted_key[0m[0;34m)[0m[0;34m[0m[0;34m[0m[0m
[0m[1;32m   3622[0m             [0;32mexcept[0m [0mKeyError[0m [0;32mas[0m [0merr[0m[0;34m:[0m[0;34m[0m[0;34m[0m[0m

[0;32m/Library/Frameworks/Python.framework/Versions/3.10/lib/python3.10/site-packages/pandas/_libs/index.pyx[0m in [0;36mpandas._libs.index.IndexEngine.get_loc[0;34m()[0m

[0;32m/Library/Frameworks/Python.framework/Versions/3.10/lib/python3.10/site-packages/pandas/_libs/index.pyx[0m in [0;36mpandas._libs.index.IndexEngine.get_loc[0;34m()[0m

[0;32mpandas/_libs/hashtable_class_helper.pxi[0m in [0;36mpandas._libs.hashtable.PyObjectHashTable.get_item[0;34m()[0m

[0;32mpandas/_libs/hashtable_class_helper.pxi[0m in [0;36mpandas._libs.hashtable.PyObjectHashTable.get_item[0;34m()[0m

[0;31mKeyError[0m: 'knn_best_score'

The above exception was the direct cause of the following exception:

[0;31mKeyError[0m                                  Traceback (most recent call last)
[0;32m/var/folders/r0/0wztzwz955z09qc9871xwxdc0000gn/T/ipykernel_16877/2697417560.py[0m in [0;36m<module>[0;34m[0m
[1;32m      3[0m [0mglue[0m[0;34m([0m[0;34m"para1"[0m[0;34m,[0m [0mtuned[0m[0;34m.[0m[0miloc[0m[0;34m[[0m[0;36m0[0m[0;34m][0m[0;34m[[0m[0;34m"kneighborsclassifier__n_neighbors"[0m[0;34m][0m[0;34m)[0m[0;34m[0m[0;34m[0m[0m
[1;32m      4[0m [0mglue[0m[0;34m([0m[0;34m"para2"[0m[0;34m,[0m [0mtuned[0m[0;34m.[0m[0miloc[0m[0;34m[[0m[0;36m0[0m[0;34m][0m[0;34m[[0m[0;34m"kneighborsclassifier__weights"[0m[0;34m][0m[0;34m)[0m[0;34m[0m[0;34m[0m[0m
[0;32m----> 5[0;31m [0mglue[0m[0;34m([0m[0;34m"recall"[0m[0;34m,[0m [0mnp[0m[0;34m.[0m[0maround[0m[0;34m([0m[0mtuned[0m[0;34m.[0m[0miloc[0m[0;34m[[0m[0;36m0[0m[0;34m][0m[0;34m[[0m[0;34m"knn_best_score"[0m[0;34m][0m[0;34m,[0m [0;36m3[0m[0;34m)[0m[0;34m)[0m[0;34m[0m[0;34m[0m[0m
[0m
[0;32m/Library/Frameworks/Python.framework/Versions/3.10/lib/python3.10/site-packages/pandas/core/series.py[0m in [0;36m__getitem__[0;34m(self, key)[0m
[1;32m    956[0m [0;34m[0m[0m
[1;32m    957[0m         [0;32melif[0m [0mkey_is_scalar[0m[0;34m:[0m[0;34m[0m[0;34m[0m[0m
[0;32m--> 958[0;31m             [0;32mreturn[0m [0mself[0m[0;34m.[0m[0m_get_value[0m[0;34m([0m[0mkey[0m[0;34m)[0m[0;34m[0m[0;34m[0m[0m
[0m[1;32m    959[0m [0;34m[0m[0m
[1;32m    960[0m         [0;32mif[0m [0mis_hashable[0m[0;34m([0m[0mkey[0m[0;34m)[0m[0;34m:[0m[0;34m[0m[0;34m[0m[0m

[0;32m/Library/Frameworks/Python.framework/Versions/3.10/lib/python3.10/site-packages/pandas/core/series.py[0m in [0;36m_get_value[0;34m(self, label, takeable)[0m
[1;32m   1067[0m [0;34m[0m[0m
[1;32m   1068[0m         [0;31m# Similar to Index.get_value, but we do not fall back to positional[0m[0;34m[0m[0;34m[0m[0m
[0;32m-> 1069[0;31m         [0mloc[0m [0;34m=[0m [0mself[0m[0;34m.[0m[0mindex[0m[0;34m.[0m[0mget_loc[0m[0;34m([0m[0mlabel[0m[0;34m)[0m[0;34m[0m[0;34m[0m[0m
[0m[1;32m   1070[0m         [0;32mreturn[0m [0mself[0m[0;34m.[0m[0mindex[0m[0;34m.[0m[0m_get_values_for_loc[0m[0;34m([0m[0mself[0m[0;34m,[0m [0mloc[0m[0;34m,[0m [0mlabel[0m[0;34m)[0m[0;34m[0m[0;34m[0m[0m
[1;32m   1071[0m [0;34m[0m[0m

[0;32m/Library/Frameworks/Python.framework/Versions/3.10/lib/python3.10/site-packages/pandas/core/indexes/base.py[0m in [0;36mget_loc[0;34m(self, key, method, tolerance)[0m
[1;32m   3621[0m                 [0;32mreturn[0m [0mself[0m[0;34m.[0m[0m_engine[0m[0;34m.[0m[0mget_loc[0m[0;34m([0m[0mcasted_key[0m[0;34m)[0m[0;34m[0m[0;34m[0m[0m
[1;32m   3622[0m             [0;32mexcept[0m [0mKeyError[0m [0;32mas[0m [0merr[0m[0;34m:[0m[0;34m[0m[0;34m[0m[0m
[0;32m-> 3623[0;31m                 [0;32mraise[0m [0mKeyError[0m[0;34m([0m[0mkey[0m[0;34m)[0m [0;32mfrom[0m [0merr[0m[0;34m[0m[0;34m[0m[0m
[0m[1;32m   3624[0m             [0;32mexcept[0m [0mTypeError[0m[0;34m:[0m[0;34m[0m[0;34m[0m[0m
[1;32m   3625[0m                 [0;31m# If we have a listlike key, _check_indexing_error will raise[0m[0;34m[0m[0;34m[0m[0m

[0;31mKeyError[0m: 'knn_best_score'
KeyError: 'knn_best_score'

